Workbook

Sheet Info
A1: Simulated and experimentally determined data for the manuscript:
A3: Proteome regulation patterns determine Escherichia coli wild-type and mutant phenotypes
A4: Tobias B. Alter; Lars M. Blank; Birgitta E. Ebert
A6: Content:
B8: Sheet | C8: Description
B9: Sheet 1 | C9: Curated enzymatic data used to build the protein allocation model (data shown in Fig. S8)
B10: Sheet 2 | C10: Transformation of experimentally determined protein mass data to dry cell weight related units
B11: Sheet 3 | C11: Cell volumes calculated from growth rates based on the experimentally justified relation of Volkmer et al. (2011) (doi: 10.1371/journal.pone.0023126)
B12: Sheet 4 | C12: (Data shown in Fig 3) Experimental data of growth, acetate secretion, oxygen uptake, and carbon dioxide production rates for E. coli for a range of glucose uptake rates
B13: Sheet 5 | C13: (Data shown in Fig 4) Comparison between experimentally determined and predicted growth and acetate secretion rates using several substrates as sole carbon sources.
B14: Sheet 6 | C14: (Data shown in Fig 5) Comparison between predictions and experimental data of intracellular fluxes of the central carbon metabolism of E. coli grown on a glucose minimal medium.
B15: Sheet 7 | C15: (Data shown in Fig S2) Comparison of predicted and experimentally determined intracellular fluxes of the central carbon metabolism of E. coli grown on several alternative carbon sources.
B16: Sheet 8 | C16: (Data shown in Fig 6) Experimentally determined, normalized growth rates for a range of eGFP expression strengths and respective eGFP concentrations in E. coli
B17: Sheet 9 | C17: (Data shown in Fig 7) Comparison of predicted growth and acetate secretion rates of single-gene deletion E. coli mutants with experimentally determined values
B18: Sheet 10 | C18: (Data shown in Fig 8) Comparison of predicted relative growth, glucose uptake and acetate secretion rates of single-gene deletion E. coli mutants with experimentally determined values
B19: Sheet 11 | C19: (Data shown in Fig 9) Comparison of predicted intracellular flux rates of single-gene deletion mutants with experimentally determined values
... B25: Sheet 17 | C25: (Data shown in Fig S8) Comparison between turnover numbers from the in vitro curated data set (cf. Sheet 1) and a data set derived from a machine learning ensemble model published by Heckmann et al. (2018) (doi: 10.1038/s41467-018-07652-6)

Sheet Sheet 1
A1: Curated enzymatic data used to build the protein allocation model
A2: Reaction IDs are taken from the BIGG database (http://bigg.ucsd.edu/)
A3: Basis stoichiometric reconstruction: iML1515 (Escherichia coli K12 MG1655)
F5: in vitro curated
A6: Reaction ID | B6: Reaction name | C6: Reaction equation | D6: EC number | E6: Enzyme molar mass [g/mol] | F6: Turnover number (kcat) [1/s]
A7: ALATA_D2 | B7: D-alanine transaminase | C7: pydx5p_c + ala__D_c -> pyam5p_c + pyr_c | D7: 2.1.2.1, 4.1.2.48 | E7: 40904.485 | F7: 6.8625
A8: SHCHD2 | B8: Sirohydrochlorin dehydrogenase (NAD) | C8: nad_c + dscl_c -> h_c + scl_c + nadh_c | D8: 1.3.1.76 | E8: 49950 | F8: 0.45
A9: CPPPGO | B9: Coproporphyrinogen oxidase (O2 required) | C9: 2 h_c + o2_c + cpppg3_c -> 2 h2o_c + pppg9_c + 2 co2_c | D9: 1.3.3.3 | E9: 34321.49 | F9: 0.003
A10: GTHOr_f | B10: Glutathione oxidoreductase | C10: h_c + nadph_c + gthox_c -> 2 gthrd_c + nadp_c | D10: 1.8.1.7 | E10: 48771.05 | F10: 733.3
A11: DHORD5 | B11: Dihydroorotic acid (menaquinone-8) | C11: dhor__S_c + mqn8_c -> orot_c + mql8_c | D11: 1.3.5.2 | E11: 36773.46 | F11: 82
A12: GLYCTO2 | B12: Glycolate oxidase | C12: glyclt_c + q8_c -> glx_c + q8h2_c | D12: 1.1.3.15 | E12: 137242.88 | F12: 15.7
A13: GLYCTO3 | B13: Glycolate oxidase | C13: glyclt_c + mqn8_c -> glx_c + mql8_c | D13: 1.1.3.15 | E13: 137242.88 | F13: 15.7
A14: GLYCTO4 | B14: Glycolate oxidase | C14: glyclt_c + 2dmmq8_c -> glx_c + 2dmmql8_c | D14: 1.1.3.15 | E14: 137242.88 | F14: 15.7
A15: PFK_3 | B15: Phosphofructokinase (s7p) | C15: atp_c + s7p_c -> h_c + adp_c + s17bp_c | D15: 2.7.1.11 | E15: 34840.99 | F15: 31.0185
A16: TRPS2 | B16: Tryptophan synthase (indole) | C16: ser__L_c + indole_c -> trp__L_c + h2o_c | D16: 4.2.1.20 | E16: 71687.15 | F16: 3.695
A17: G3PD5 | B17: Glycerol-3-phosphate dehydrogenase (ubiquinone-8) | C17: glyc3p_c + q8_c -> dhap_c + q8h2_c | D17: 1.1.5.3 | E17: 102566.01 | F17: 33.3
A18: LEUTAi | B18: Leucine transaminase (irreversible) | C18: 4mop_c + glu__L_c -> akg_c + leu__L_c | D18: 2.6.1.42 | E18: 38814.565 | F18: 15.655
... A563: BSORx | B563: Biotin sulfoxide reductase | C563: h_c + nadh_c + btnso_c -> nad_c + h2o_c + btn_c | D563: 1.-.-.- | E563: 85848.07 | F563: 93.556479
A564: GLUtex_f | B564: L-glutamate transport via diffusion (extracellular to periplasm) | C564: glu__L_e -> glu__L_p | E564: 39959.482 | F564: 100000000
A565: GLYtex_f | B565: Glycine transport via diffusion (extracellular to periplasm) | C565: gly_e -> gly_p | E565: 39959.482 | F565: 100000000
A566: GLYALDtex_f | B566: Glyceraldehyde transport via diffusion (extracellular to periplasm) | C566: glyald_e -> glyald_p | E566: 39959.482 | F566: 100000000
A567: GLYBtex_f | B567: Glycine betaine transport via diffusion (extracellular to periplasm) | C567: glyb_e -> glyb_p | E567: 39959.482 | F567: 100000000
A568: GLYCtex_f | B568: Glycerol transport via diffusion (extracellular to periplasm) | C568: glyc_e -> glyc_p | E568: 39959.482 | F568: 100000000
A569: GLYC3Ptex_f | B569: Glycerol-3-phosphate transport via diffusion (extracellular to periplasm) | C569: glyc3p_e -> glyc3p_p | E569: 39959.482 | F569: 100000000
A570: GLYCLTtex_f | B570: Glycolate transport via diffusion (extracellular to periplasm) | C570: glyclt_e -> glyclt_p | E570: 39959.482 | F570: 100000000
A571: GTPtex_f | B571: GTP transport via diffusion (extracellular to periplasm) | C571: gtp_e -> gtp_p | E571: 39959.482 | F571: 100000000
A572: GUAtex_f | B572: Guanine transport via diffusion (extracellular to periplasm) | C572: gua_e -> gua_p | E572: 33587.89 | F572: 100000000
A573: Htex_f | B573: Proton transport via diffusion (extracellular to periplasm) | C573: h_e -> h_p | E573: 39959.482 | F573: 100000000
A574: H2tex_f | B574: Hydrogen transport via diffusion (extracellular to periplasm) | C574: h2_e -> h2_p | E574: 39959.482 | F574: 100000000
A575: H2Otex_f | B575: H2O transport via diffusion (extracellular to periplasm) | C575: h2o_e -> h2o_p | E575: 37021.28 | F575: 100000000
A576: FACOAL160t2pp | B576: Fatty-acid-CoA ligase (hexadecanoate transport via vectoral Co-A coupling) | C576: hdca_p + h_p + atp_c + coa_c -> h_c + ppi_c + pmtcoa_c + amp_c | D576: 6.2.1.3 | E576: 61550.725 | F576: 0.029
A577: FACOAL180t2pp | B577: Fatty-acid-CoA ligase (octadecanoate transport via vectoral Co-A coupling) | C577: h_p + atp_c + ocdca_p + coa_c -> h_c + ppi_c + stcoa_c + amp_c | D577: 6.2.1.3 | E577: 61550.725 | F577: 0.029
A578: SPODMpp | B578: Superoxide dismutase | C578: 2 h_p + 2 o2s_p -> o2_p + h2o2_p | D578: 1.15.1.1 | E578: 17680.45 | F578: 22300
A579: NO3R1bpp | B579: Nitrate reductase (Ubiquinol-8) | C579: q8h2_c + no3_p -> h2o_p + no2_p + q8_c | D579: 1.9.6.1 | E579: 189159.49 | F579: 94.286
A580: PHYTSpp | B580: Phytase (periplasm) | C580: 6 h2o_p + minohp_p -> inost_p + 6 pi_p | D580: 3.1.3.26 | E580: 47055.46 | F580: 6931
A581: PPTHpp | B581: Phosphonate hydrogenase (periplasm) | C581: ppt_p + h2o_p -> pi_p + h2_p | D581: 3.1.3.1 | E581: 49437.14 | F581: 33
A582: NO3R2pp | B582: Nitrate reductase (Menaquinol-8) (periplasm) | C582: 2 h_c + mql8_c + no3_c -> 2 h_p + h2o_c + mqn8_c + no2_c | D582: 1.7.5.1 | E582: 250670.71 | F582: 68
A583: NTP3pp | B583: Nucleoside-triphosphatase (GTP) (periplasm) | C583: h2o_p + gtp_p -> h_p + gdp_p + pi_p | D583: 3.1.3.2, 3.1.3.26 | E583: 47055.46 | F583: 250.5
A584: NO3R2bpp | B584: Nitrate reductase (Menaquinol-8) (periplasm) | C584: mql8_c + no3_p -> h2o_p + no2_p + mqn8_c | D584: 1.9.6.1 | E584: 132398.9 | F584: 94.286
A585: THD2pp | B585: NAD(P) transhydrogenase (periplasm) | C585: 2 h_p + nadp_c + nadh_c -> 2 h_c + nad_c + nadph_c | D585: 1.6.1.2 | E585: 103325.62 | F585: 40.88335
...

Sheet Sheet 2
B1: Environmental condition / substrate
B2: Glucose | C2: LB | D2: Glycerol + AA | E2: Acetate | F2: Fumarate | G2: Glucosamine | H2: Glycerol | I2: Pyruvate | J2: Chemostat µ=0.5 | K2: Chemostat µ=0.35 | L2: Chemostat µ=0.20 | M2: Chemostat µ=0.12 | N2: Stationary phase 1 day | O2: Stationary phase 3 days | P2: Osmotic-stress glucose | Q2: 42°C glucose | R2: pH6 glucose | S2: Xylose | T2: Mannose | U2: Galactose | V2: Succinate | W2: Fructose
A3: Total protein abundance | B3: 5070439.8 | C3: 8357873.3 | D3: 7057371.6 | E3: 3817955.1 | F3: 4389989.3 | G3: 4681894.1 | H3: 4647420.6 | I3: 4193699 | J3: 4553456.6 | K3: 3992834.9 | L3: 3432399.4 | M3: 3113584 | N3: 3389379.7 | O3: 3272427.2 | P3: 5294648 | Q3: 5288227 | R3: 5507866.1 | S3: 4919908.1 | T3: 4502698.3 | U3: 3793619.1 | V3: 4451684 | W3: 5150906.9
A4: protein copies/cell
A5: Molar abundance | B5: =(B3/(6.022*10^23))*(10^9) -> 8.4198602e-09 | C5: =(C3/(6.022*10^23))*(10^9) -> 1.38789e-08 | D5: =(D3/(6.022*10^23))*(10^9) -> 1.1719315e-08 | E5: =(E3/(6.022*10^23))*(10^9) -> 6.3400117e-09 | F5: =(F3/(6.022*10^23))*(10^9) -> 7.2899192e-09 | G5: =(G3/(6.022*10^23))*(10^9) -> 7.7746499e-09 | H5: =(H3/(6.022*10^23))*(10^9) -> 7.7174039e-09 | I5: =(I3/(6.022*10^23))*(10^9) -> 6.9639638e-09 | ... W5: =(W3/(6.022*10^23))*(10^9) -> 8.553482e-09
A6: nmol/cell
A7: Molar concentration | B7: =((B5/'Sheet 3'!B5)/$B$23)/1000 -> 10.469641 | C7: =((C5/'Sheet 3'!C5)/$B$23)/1000 -> 12.055354 | D7: =((D5/'Sheet 3'!D5)/$B$23)/1000 -> 11.414451 | E7: =((E5/'Sheet 3'!E5)/$B$23)/1000 -> 10.292783 | F7: =((F5/'Sheet 3'!F5)/$B$23)/1000 -> 10.700207 | G7: =((G5/'Sheet 3'!G5)/$B$23)/1000 -> 11.072617 | H7: =((H5/'Sheet 3'!H5)/$B$23)/1000 -> 10.911141 | I7: =((I5/'Sheet 3'!I5)/$B$23)/1000 -> 10.383355 | ... W7: =((W5/'Sheet 3'!W5)/$B$23)/1000 -> 10.758601
A8: mumol/gCDW
A9: Protein flux
A12: Total protein mass | B12: 243.19403 | C12: 366.96599 | D12: 326.55115 | E12: 196.36217 | F12: 217.28882 | G12: 225.42855 | H12: 225.49559 | I12: 213.86997 | J12: 230.38334 | K12: 205.3962 | L12: 178.1886 | M12: 162.79103 | N12: 139.60221 | O12: 138.86696 | P12: 238.29922 | Q12: 255.07198 | R12: 250.57583 | S12: 237.72469 | T12: 224.95989 | U12: 189.03237 | V12: 220.5373 | W12: 252.86642
A13: fg per cell
A14: Total protein concentration | B14: =(B12)/'Sheet 3'!B4 -> 81.1517 | C14: =(C12)/'Sheet 3'!C4 -> 85.539857 | D14: =(D12)/'Sheet 3'!D4 -> 85.353591 | E14: =(E12)/'Sheet 3'!E4 -> 85.549676 | F14: =(F12)/'Sheet 3'!F4 -> 85.590317 | G14: =(G12)/'Sheet 3'!G4 -> 86.158105 | H14: =(H12)/'Sheet 3'!H4 -> 85.556847 | I14: =(I12)/'Sheet 3'!I4 -> 85.575371 | ... W14: =(W12)/'Sheet 3'!W4 -> 85.353591
A15: g protein / L
A16: Total protein concentration | B16: =B14/$B$23 -> 0.30239864 | C16: =C14/$B$23 -> 0.3187504 | D16: =D14/$B$23 -> 0.31805631 | E16: =E14/$B$23 -> 0.31878699 | F16: =F14/$B$23 -> 0.31893843 | G16: =G14/$B$23 -> 0.3210542 | H16: =H14/$B$23 -> 0.31881371 | I16: =I14/$B$23 -> 0.31888273 | ... W16: =W14/$B$23 -> 0.31805631
A17: g protein / g biomass_cdw
A18: Mean protein concentration | B18: =AVERAGE(B16:W16) -> 0.31864834
A19: Std protein concentration | B19: =_xlfn.STDEV.S(B16:W16) -> 0.0041252726
A22: Parameters:
A23: Molar cell weight [g/mol] | B23: 268.36

Sheet Sheet 3
B1: Environmental condition/substrate
B2: Glucose | C2: LB | D2: Glycerol + AA | E2: Acetate | F2: Fumarate | G2: Glucosamine | H2: Glycerol | I2: Pyruvate | J2: Chemostat µ=0.5 | K2: Chemostat µ=0.35 | L2: Chemostat µ=0.20 | M2: Chemostat µ=0.12 | N2: Stationary phase 1 day | O2: Stationary phase 3 days | P2: Osmotic-stress glucose | Q2: 42°C glucose | R2: pH6 glucose | S2: Xylose | T2: Mannose | U2: Galactose | V2: Succinate | W2: Fructose
A3: Specific growth rate [1/h] | B3: 0.67 | C3: 1.78 | D3: 1.27 | E3: 0.3 | F3: 0.42 | G3: 0.46 | H3: 0.47 | I3: 0.4 | J3: 0.5 | K3: 0.35 | L3: 0.2 | M3: 0.12 | N3: 0 | O3: 0 | P3: 0.55 | Q3: 0.66 | R3: 0.63 | S3: 0.55 | T3: 0.47 | U3: 0.26 | V3: 0.44 | W3: 0.65
A4: Cell volume [fL] | B4: 2.996783 | C4: 4.29 | D4: 3.825863 | E4: 2.2953 | F4: 2.538708 | G4: 2.616452 | H4: 2.635623 | I4: 2.4992 | J4: 2.6925 | K4: 2.398575 | L4: 2.0808 | M4: 1.901568 | N4: 1.595847 | O4: 1.595847 | P4: 2.785175 | Q4: 2.979732 | R4: 2.927943 | S4: 2.785175 | T4: 2.635623 | U4: 2.210772 | V4: 2.577792 | W4: 2.962575
A5: Cell volume [L] | B5: =B4/(10^15) -> 2.996783e-15 | C5: =C4/(10^15) -> 4.29e-15 | D5: =D4/(10^15) -> 3.825863e-15 | E5: =E4/(10^15) -> 2.2953e-15 | F5: =F4/(10^15) -> 2.538708e-15 | G5: =G4/(10^15) -> 2.616452e-15 | H5: =H4/(10^15) -> 2.635623e-15 | I5: =I4/(10^15) -> 2.4992e-15 | ... W5: =W4/(10^15) -> 2.962575e-15

Sheet Sheet 4
A1: Experimental data of growth, acetate secretion, oxygen uptake, and carbon dioxide production rates for E. coli for a range of glucose uptake rates
B4: Growth rate | C4: Glucose uptake rate | D4: Biomass yield | E4: Acetate yield | F4: Acetate secretion rate | G4: CO2 yield | H4: CO2 production rate | I4: O2 uptake rate | J4: Source
B5: 1/h | C5: mmol/gDW/h | D5: gDW/gGLC | E5: gAC/gGLC | F5: mmol/gDW/h | G5: gCO2/gGLC | H5: mmol/gDW/h | I5: mmol/gDW/h
B6: 0.24 | C6: =(B6/D6)/0.1802 -> 3.0269398 | D6: 0.44 | E6: 0 | F6: =E6*B6 -> 0 | G6: 27.56 | H6: =G6*B6 -> 6.6144 | J6: Valgepea et al. 2010 (doi: 10.1186/1752-0509-4-166)
B7: 0.24 | C7: =(B7/D7)/0.1802 -> 3.3296337 | D7: 0.4 | E7: 0 | F7: =E7*B7 -> 0 | G7: 30.12 | H7: =G7*B7 -> 7.2288
B8: 0.3 | C8: =(B8/D8)/0.1802 -> 3.6191671 | D8: 0.46 | E8: 0.53 | F8: =E8*B8 -> 0.159 | G8: 27.55 | H8: =G8*B8 -> 8.265
B9: 0.3 | C9: =(B9/D9)/0.1802 -> 4.060529 | D9: 0.41 | E9: 0.9 | F9: =E9*B9 -> 0.27 | G9: 27.19 | H9: =G9*B9 -> 8.157
B10: 0.4 | C10: =(B10/D10)/0.1802 -> 5.0448996 | D10: 0.44 | E10: 1.7 | F10: =E10*B10 -> 0.68 | G10: 26.24 | H10: =G10*B10 -> 10.496
B11: 0.4 | C11: =(B11/D11)/0.1802 -> 5.2851329 | D11: 0.42 | E11: 1.56 | F11: =E11*B11 -> 0.624 | G11: 23.86 | H11: =G11*B11 -> 9.544
B12: 0.51 | C12: =(B12/D12)/0.1802 -> 6.5818341 | D12: 0.43 | E12: 3.25 | F12: =E12*B12 -> 1.6575
B13: 0.51 | C13: =(B13/D13)/0.1802 -> 6.9028992 | D13: 0.41 | E13: 3.35 | F13: =E13*B13 -> 1.7085 | G13: 21.19 | H13: =G13*B13 -> 10.8069
B14: 0.65 | C14: 7.6 | D14: 0.48 | F14: 4.8 | J14: Perrenoud et al. 2005 (doi: 10.1128/JB.187.9.3171-3179.2005)
B15: 0.04 | C15: 0.9 | D15: =B15/(C15*0.1802) -> 0.24663954 | E15: 0 | F15: 0 | J15: Nanchen et al. 2006 (doi: 10.1128/AEM.72.2.1164)
B16: 0.05 | C16: 1.2 | D16: =B16/(C16*0.1802) -> 0.23122457 | E16: 0 | F16: 0
B17: 0.06 | C17: 1.1 | D17: =B17/(C17*0.1802) -> 0.30269398 | E17: 0 | F17: 0
B18: 0.09 | C18: 1.7 | D18: =B18/(C18*0.1802) -> 0.29379121 | E18: 0 | F18: 0
B19: 0.09 | C19: 1.8 | D19: =B19/(C19*0.1802) -> 0.27746948 | E19: 0 | F19: 0
B20: 0.11 | C20: 2 | D20: =B20/(C20*0.1802) -> 0.30521643 | E20: 0 | F20: 0
B21: 0.19 | C21: 2.8 | D21: =B21/(C21*0.1802) -> 0.37656572 | E21: 0 | F21: 0
B22: 0.29 | C22: 4.2 | D22: =B22/(C22*0.1802) -> 0.38317214 | E22: 0 | F22: 0
B23: 0.31 | C23: 4.6 | D23: =B23/(C23*0.1802) -> 0.3739806 | E23: 0 | F23: 0
B24: 0.4 | C24: 5.7 | D24: =B24/(C24*0.1802) -> 0.38943085 | E24: 0 | F24: 0
B25: 0.41 | C25: 5.8 | D25: =B25/(C25*0.1802) -> 0.39228443 | E25: 0 | F25: 0
B26: 0.21 | C26: 2.66 | D26: =B26/(C26*0.1802) -> 0.4381097 | J26: Peebo et al. 2015 (doi: 10.1039/C4MB00721B)
B27: 0.31 | C27: 3.81 | D27: =B27/(C27*0.1802) -> 0.45152514
B28: 0.41 | C28: 4.91 | D28: =B28/(C28*0.1802) -> 0.46339098
B29: 0.51 | C29: 6.24 | D29: =B29/(C29*0.1802) -> 0.45355588
B30: 0.22 | C30: 2.78 | D30: =B30/(C30*0.1802) -> 0.43916033
B31: 0.26 | C31: 3.25 | D31: =B31/(C31*0.1802) -> 0.44395117
B32: 0.36 | C32: 4.36 | D32: =B32/(C32*0.1802) -> 0.45820648
B33: 0.46 | C33: 5.52 | D33: =B33/(C33*0.1802) -> 0.46244913
B34: 0.51 | C34: 6.24 | D34: =B34/(C34*0.1802) -> 0.45355588
B35: 0.1 | C35: 1.52 | D35: =B35/(C35*0.1802) -> 0.36509142 | F35: 0 | J35: Folsom et al. 2014 (doi: 10.1128/JB.01606-14)
B36: 0.2 | C36: 2.47 | D36: =B36/(C36*0.1802) -> 0.44934328 | F36: 0
B37: 0.3 | C37: 4.25 | D37: =B37/(C37*0.1802) -> 0.39172162 | F37: 0
B38: 0.4 | C38: 5.65 | D38: =B38/(C38*0.1802) -> 0.39287714 | F38: 0
B39: =(C39*0.1802)*D39 -> 0.053081052 | C39: 0.69970564 | D39: 0.42098765 | F39: 0 | H39: 1.987149 | I39: 2.1618357 | J39: Vemuri et al. 2006 (doi: 10.1128/AEM.72.5.3653)
B40: =(C40*0.1802)*D40 -> 0.10184035 | C40: 1.2046656 | D40: 0.4691358 | F40: 0 | H40: 2.8081866 | I40: 2.8864734
B41: =(C41*0.1802)*D41 -> 0.19179894 | C41: 2.1542661 | D41: 0.49407407 | F41: 0 | H41: 4.5311756 | I41: 4.7463768
B42: =(C42*0.1802)*D42 -> 0.29827191 | C42: 3.3451445 | D42: 0.49481481 | F42: 0 | H42: 6.5909091 | I42: 10
...

Sheet Sheet 5
A1: Comparison between experimentally determined and predicted growth and acetate secretion rates using several substrates as sole carbon sources.
A2: Experimental data taken from Gerosa et al. (2015) (doi: 10.1016/j.cels.2015.09.008)
A4: Model: iML1515 including protein allocation and enzymatic constraints
A5: Upper bound of substrate uptake rates were constrained to observed values
B8: Substrate | C8: Growth rate | E8: Acetate production rate | G8: Substrate uptake rate
C9: 1/h | E9: mmol/gDW/h | G9: mmol/gDW/h
C10: Experimental | D10: Predicted | E10: Experimental | F10: Predicted | G10: Experimental
B11: Glucose | C11: 0.65 | D11: 0.65889 | E11: 6.83 | F11: 6.83082 | G11: 9.65
B12: Fructose | C12: 0.49 | D12: 0.588 | E12: 3.33 | F12: 4.68472 | G12: 8.33
B13: Galactose | C13: 0.18 | D13: 0.14537 | E13: 0 | F13: 0 | G13: 1.969
B14: Acetate | C14: 0.29 | D14: 0.265 | E14: -- | F14: 0 | G14: 13.58
B15: Glycerol | C15: 0.49 | D15: 0.22598 | E15: 0.6 | F15: 0 | G15: 4.94
B16: Gluconate | C16: 0.59 | D16: 0.4746 | E16: 5 | F16: 3.66293 | G16: 7.28
B17: Pyruvate | C17: 0.39 | D17: 0.34386 | E17: 11.91 | F17: 19.33915 | G17: 26.71
B18: Succinate | C18: 0.51 | D18: 0.48738 | E18: 3.32 | F18: 9.4021 | G18: 15.9
B19: Glucose (anaerobic) | C19: 0.33 | D19: 0.33196 | E19: 7.3 | F19: 7.15895 | G19: 13.1
B20: Xylose (Anaerobic) | C20: 0.13 | D20: 0.1439 | E20: 5.5 | F20: 3.12879 | G20: 10.8

Sheet Sheet 6
A1: Comparison between predictions and experimental data of intracellular fluxes of the central carbon metabolism of E. coli grown on a glucose minimal medium.
A3: Model: iML1515 including protein allocation and enzymatic constraints
A4: Upper bound of glucose uptake rate was constrained to measured values
A5: Excess enzyme sector was parametrized according to a methodically derived maximum glucose uptake rate of 9.82 mmol/gDW/h
B8: Reaction ID (iML1515) | C8: Gerosa et al. 2015 | F8: Reaction ID (iML1515) | G8: Rijsewijk et al. 2011 | J8: Reaction ID (iML1515) | K8: Nanchen et al. 2015
C9: Flux rate | G9: Flux rate | K9: Flux rate
C10: mmol/gDW/h | G10: mmol/gDW/h | K10: mmol/gDW/h
C11: Experimental | D11: Predicted | G11: Experimental | H11: Predicted | K11: Experimental | L11: Predicted | M11: Experimental | N11: Predicted | O11: Experimental | P11: Predicted | Q11: Experimental | R11: Predicted
A12: Glucose uptake rate | B12: EX_glc_e_b | C12: 9.65 | F12: EX_glc_e_b | G12: 8.26 | J12: EX_glc_e_b | K12: 1.67 | M12: 2.8 | O12: 4.22 | Q12: 5.65
B13: EX_ac_e_f | C13: 6.82702 | D13: 6.83536 | F13: BIOMASS_Ec_iML1515_WT_75p37M | G13: 0.61 | H13: 0.57215 | J13: BIOMASS_Ec_iML1515_WT_75p37M | K13: 0.085 | L13: 0.12122 | M13: 0.187 | N13: 0.21865 | O13: 0.286 | P13: 0.31946 | Q13: 0.399 | R13: 0.40901
B14: PGI_b | C14: 5.69997 | D14: 6.71756 | F14: EX_ac_e_f | G14: 4.89 | H14: 5.27944 | J14: EX_ac_e_f | K14: 0 | L14: 0 | M14: 0 | N14: 0 | O14: 0 | P14: 0.77262 | Q14: 0 | R14: 2.36742
B15: PFK | C15: 7.05848 | D15: 8.01715 | F15: GLCptspp | G15: 8.13 | H15: 8.26 | J15: HEX1 | K15: 1.6703 | L15: 0 | M15: 2.8385 | N15: 0 | O15: 4.3081 | P15: 0 | Q15: 5.7062 | R15: 0
B16: FBA_f | C16: 7.05848 | D16: 8.01715 | F16: G6PDH2r_f | G16: 2.29 | H16: 1.81648 | J16: G6PDH2r_f | K16: 0.4617 | L16: 0 | M16: 1.2632 | N16: 0.11793 | O16: 1.6394 | P16: 0.56021 | Q16: 2.0589 | R16: 0.71724
B17: TPI_f | C17: 7.05848 | D17: 7.90998 | F17: GND | G17: 1.53 | H17: 1.81648 | J17: GND | K17: 0.3482 | L17: 0 | M17: 0.9684 | N17: 0.11793 | O17: 1.2613 | P17: 0.56021 | Q17: 1.6495 | R17: 0.71724
B18: PYK | C18: 2.48731 | D18: 3.37695 | F18: PGI_f | G18: 5.81 | H18: 6.33198 | J18: PGI_f | K18: 1.204 | L18: 1.64637 | M18: 1.5654 | N18: 2.63945 | O18: 2.6534 | P18: 3.59752 | Q18: 3.6259 | R18: 4.85303
B19: PDH | C19: 11.29846 | D19: 10.09992 | F19: EDA | G19: 0.77 | H19: 0 | J19: EDA | K19: 0.1135 | L19: 0 | M19: 0.2947 | N19: 0 | O19: 0.378 | P19: 0 | Q19: 0.4094 | R19: 0
B20: EDA | C20: 1.08699 | D20: 0 | F20: PFK | G20: 6.48 | H20: 7.04613 | J20: PFK | K20: 1.3872 | L20: 1.54111 | M20: 2.0973 | N20: 2.5282 | O20: 3.3059 | P20: 3.69358 | Q20: 4.4416 | R20: 4.97602
B21: RPI_f | C21: 1.42744 | D21: 0 | F21: TKT1_f | G21: 0.49 | H21: 0.50263 | J21: TKT1_f | K21: 0.1143 | L21: 0 | M21: 0.3134 | N21: 0 | O21: 0.3972 | P21: 0.1293 | Q21: 0.5033 | R21: 0.16555
B22: RPE_f | C22: 1.40485 | D22: 1.36818 | F22: TKT2_f | G22: 0.23 | H22: 0.27105 | J22: TKT2_f | K22: 0.075 | L22: 0 | M22: 0.2317 | N22: 0 | O22: 0.2758 | P22: 0 | Q22: 0.3411 | R22: 0
B23: TKT2_f | C23: 0.58464 | D23: 0.5507 | F23: TALA_f | G23: 0.49 | H23: 0.48398 | J23: TALA_f | K23: 0.1143 | L23: 0 | M23: 0.3134 | N23: 0 | O23: 0.3972 | P23: 0.11889 | Q23: 0.5033 | R23: 0.15221
B24: PPC | C24: 2.45333 | D24: 2.97552 | F24: GAPD_f | G24: 13.88 | H24: 14.3165 | J24: GAPD_f | K24: 2.9538 | L24: 3.00146 | M24: 4.7008 | N24: 4.95002 | O24: 7.2338 | P24: 7.36102 | Q24: 9.588 | R24: 9.91857
... B32: BIOMASS_Ec_iML1515_WT_75p37M | C32: 0.65 | D32: 0.65914 | F32: MDH_f | G32: 0.8 | H32: 3.59211 | J32: MDH_f | K32: 2.8572 | L32: 2.00266 | M32: 3.5187 | N32: 3.69229 | O32: 3.8016 | P32: 3.5482 | Q32: 4.4536 | R32: 3.65876
F33: ME1 | G33: 0.53 | H33: 0 | J33: ME1 | K33: 0.0035 | L33: 0 | M33: 0.411 | N33: 0 | O33: 0.67 | P33: 0 | Q33: 0.4582 | R33: 0
F34: PPCK | G34: 0.32 | H34: 0 | J34: PPCK | K34: 1.1791 | L34: 0 | M34: 1.16 | N34: 0 | O34: 0.6401 | P34: 0 | Q34: 0.8769 | R34: 0
F35: PPC | G35: 2.78 | H35: 2.58284 | J35: PPC | K35: 0.5112 | L35: 0 | M35: 0.8348 | N35: 0 | O35: 1.6742 | P35: 1.44214 | Q35: 2.5861 | R35: 1.84638
F36: PTAr_f | G36: 5.48 | H36: 4.94123 | J36: ACKr_b | K36: 0 | L36: 0 | M36: 0 | N36: 0 | O36: 0 | P36: 0.58377 | Q36: 0 | R36: 2.12564
J37: MALS | K37: 0.9634 | L37: 0.35471 | M37: 1.323 | N37: 0.90524 | O37: 0.541 | P37: 0.00028496 | Q37: 0 | R37: 0.000364836
J38: NADTRHD | K38: 0.3821 | L38: 0 | M38: 0.595 | N38: 0 | O38: 1.8731 | P38: 0 | Q38: 2.5753 | R38: 0

Sheet Sheet 7
A1: Comparison of predicted and experimentally determined intracellular fluxes of the central carbon metabolism of E. coli grown on several alternative carbon sources.
A2: Experimental data taken from Gerosa et al. (2015) (doi: 10.1016/j.cels.2015.09.008)
A4: Model: iML1515 including protein allocation and enzymatic constraints
A5: Upper bounds of substrate uptake rates were constrained to measured values
A6: Excess enzyme sector was parametrized according to a methodically derived maximum glucose uptake rate of 9.82 mmol/gDW/h
B9: Substrate: | C9: Acetate | E9: Fructose | G9: Galactose | I9: Gluconate | K9: Glycerol | M9: Pyruvate | O9: Succinate
B10: Reaction ID (iML1515) | C10: Flux rate | E10: Flux rate | G10: Flux rate | I10: Flux rate | K10: Flux rate | M10: Flux rate | O10: Flux rate
C11: mmol/gDW/h | E11: mmol/gDW/h | G11: mmol/gDW/h | I11: mmol/gDW/h | K11: mmol/gDW/h | M11: mmol/gDW/h | O11: mmol/gDW/h
C12: Experimental | D12: Predicted | E12: Experimental | F12: Predicted | G12: Experimental | H12: Predicted | I12: Experimental | J12: Predicted | K12: Experimental | L12: Predicted | M12: Experimental | N12: Predicted | O12: Experimental | P12: Predicted
B13: Substrate uptake rate | C13: 13.584 | D13: - | E13: 8.328 | F13: - | G13: 1.969 | H13: - | I13: 7.2839232 | J13: - | K13: 4.9448336 | L13: - | M13: 26.714 | N13: - | O13: 15.902 | P13: -
B14: EX_ac_e_f | C14: - | D14: - | E14: 3.32866 | F14: 4.68267 | G14: 1.96894e-08 | H14: 0 | I14: 5.00398 | J14: 3.66685 | K14: 0.597 | L14: 0 | M14: 11.91391 | N14: 19.34223 | O14: 3.32097 | P14: 9.40342
B15: PGI_b | C15: 3.42326 | D15: 0.05168 | E15: 6.19793 | F15: 0.1146 | G15: 1.36849 | H15: 1.86226 | I15: 0.03132 | J15: 0.09256 | K15: 3.4494 | L15: 0.0441 | M15: 0.89817 | N15: 0.06704 | O15: 5.59032 | P15: 0.09502
B16: PFK | C16: 1.88624 | D16: 0.28186 | E16: 2.461 | F16: 7.70291 | G16: 1.54745 | H16: 1.78829 | I16: 0.48692 | J16: 4.35106 | K16: 1.5 | L16: 0 | M16: 0.58701 | N16: 0.36565 | O16: 2.6916 | P16: 0.51825
B17: FBA_f | C17: 1.88624 | D17: 0.28186 | E17: 5.867 | F17: 7.70291 | G17: 1.54745 | H17: 1.78829 | I17: 0.48692 | J17: 4.35106 | K17: 1.4957 | L17: 0.24054 | M17: 0.58701 | N17: 0.36565 | O17: 2.6916 | P17: 0.51825
B18: TPI_f | C18: 1.88624 | D18: 0.32496 | E18: 5.867 | F18: 7.60733 | G18: 1.54745 | H18: 1.76466 | I18: 0.48692 | J18: 4.27386 | K18: 8.6403 | L18: 4.66751 | M18: 0.58701 | N18: 0.42156 | O18: 2.6916 | P18: 0.5975
B19: PYK | C19: - | D19: - | E19: 0.66904 | F19: 3.56438 | G19: 3.35734 | H19: 3.16045 | I19: 3.46459 | J19: 9.71295 | K19: 5.50726 | L19: 3.87838 | M19: - | N19: - | O19: - | P19: -
B20: PDH | C20: 0.06546 | D20: 0 | E20: 9.06883 | F20: 9.27825 | G20: 2.9427 | H20: 2.74375 | I20: 7.50554 | J20: 7.60152 | K20: 4.09774 | L20: 3.12704 | M20: 21.01739 | N20: 16.32327 | O20: 7.75208 | P20: 8.46309
B21: EDA | C21: 0.82159 | D21: 0 | E21: 8.32807e-10 | F21: 0 | G21: 0.17297 | H21: 0 | I21: 5.81896 | J21: 0 | K21: 0.01458 | L21: 0 | M21: 2.67142e-09 | N21: 0 | O21: 0.65546 | P21: 0
B22: RPI_f | C22: 1.02932 | D22: 0 | E22: 2.39854 | F22: 0 | G22: 0.2279 | H22: 0 | I22: 0.9052 | J22: 0 | K22: 1.42638 | L22: 0 | M22: 0.53893 | N22: 0 | O22: 1.97412 | P22: 0
B23: RPE_f | C23: 1.5574 | D23: 0 | E23: 3.77274 | F23: 0 | G23: 0.19078 | H23: 0 | I23: 0.55976 | J23: 4.49303 | K23: 1.98513 | L23: 0 | M23: 0.33788 | N23: 0 | O23: 2.9337 | P23: 0
B24: TKT2_f | C24: 0.71825 | D24: 0 | E24: 1.78893 | F24: 0 | G24: 0.05857 | H24: 0 | I24: 0.17098 | J24: 2.15042 | K24: 0.90438 | L24: 0 | M24: 0.09013 | N24: 0 | O24: 1.36985 | P24: 0
B25: PPC | C25: 1.77415 | D25: 0 | E25: 3.54567 | F25: 2.65382 | G25: 0.37739 | H25: 0 | I25: 1.94335 | J25: 0.72284 | K25: 1.37647 | L25: 0 | M25: 2.48945 | N25: 0 | O25: 2.01611 | P25: 0
B26: PPCK | C26: 3.11428 | D26: 1.2259 | E26: 0.35892 | F26: 0 | G26: 0.84895 | H26: 0 | I26: 0 | J26: 0 | K26: 0 | L26: 0 | M26: 1.1648 | N26: 1.23412 | O26: 2.97179 | P26: 1.74917
B27: ICDHyr_f | C27: 4.69642 | D27: 7.91568 | E27: 4.56612 | F27: 4.77512 | G27: 0.49618 | H27: 1.47569 | I27: 1.15403 | J27: 1.23839 | K27: 2.46484 | L27: 1.15371 | M27: 7.97932 | N27: 0.37422 | O27: 3.03895 | P27: 0.5304
B28: SUCDi | C28: 8.40476 | D28: 9.77554 | E28: 3.87711 | F28: 4.13615 | G28: 1.26086 | H28: 1.74421 | I28: 0.18236 | J28: 2.14294 | K28: 1.84046 | L28: 1.67444 | M28: 7.51826 | N28: 2.78717 | O28: 18.37043 | P28: 15.9026
B29: FUM_f | C29: 8.40476 | D29: 10.04616 | E29: 3.87711 | F29: 4.73631 | G29: 1.26086 | H29: 1.89261 | I29: 0.18236 | J29: 2.62769 | K29: 1.84046 | L29: 1.90539 | M29: 7.51826 | N29: 3.13825 | O29: 17.23044 | P29: 16.40022
B30: MDH_f | C30: 10.6713 | D30: 12.19438 | E30: 2.22771 | F30: 4.73683 | G30: 2.28512 | H30: 2.31926 | I30: 0.18236 | J30: 4.04876 | K30: 1.84046 | L30: 2.6722 | M30: 7.4278 | N30: 5.92522 | O30: 4.9507 | P30: 4.44832
B31: ME1 | C31: 1.87104 | D31: 0 | E31: 1.65161 | F31: 0 | G31: 0.000523765 | H31: 0 | I31: 0 | J31: 0 | K31: 0 | L31: 0 | M31: 0.19306 | N31: 0 | O31: 12.39618 | P31: 11.9519
... B33: BIOMASS_Ec_iML1515_WT_75p37M | C33: 0.29 | D33: 0.26508 | E33: 0.4924 | F33: 0.58787 | G33: 0.18 | H33: 0.14537 | I33: 0.59 | J33: 0.47483 | K33: 0.49 | L33: 0.22622 | M33: 0.39 | N33: 0.3439 | O33: 0.51 | P33: 0.48743
B34: PPS | C34: 1.6532 | D34: 0 | E34: - | F34: - | G34: - | H34: - | I34: - | J34: - | K34: - | L34: - | M34: 3.45038 | N34: 0 | O34: 3.73004 | P34: 0

Sheet Sheet 8
A1: Experimentally determined, normalized growth rates for a range of eGFP expression strengths and respective eGFP concentrations in E. coli
A2: Data taken from Bienick et al. 2014 (doi: 10.1371/journal.pone.0109105)
B5: Growth rate | C5: Growth rate error | D5: eGFP concentration | E5: eGFP concentration error
B6: 1/h | D6: g/gDW
B7: 0.56 | C7: 0.02 | D7: 0.097 | E7: 0.005
B8: 0.75 | C8: 0.07 | D8: 0 | E8: 0
B9: 0.7 | C9: 0.04 | D9: 0 | E9: 0
B10: 0.71 | C10: 0.01 | D10: 0.005 | E10: 0.001
B11: 0.73 | C11: 0.04 | D11: 0.007 | E11: 0
B12: 0.72 | C12: 0.02 | D12: 0.008 | E12: 0
B13: 0.74 | C13: 0.05 | D13: 0.008 | E13: 0.001
B14: 0.7 | C14: 0.02 | D14: 0.017 | E14: 0.001
B15: 0.72 | C15: 0.07 | D15: 0.019 | E15: 0.001
B16: 0.72 | C16: 0.02 | D16: 0.023 | E16: 0.002
B17: 0.62 | C17: 0 | D17: 0.041 | E17: 0.002
B18: 0.59 | C18: 0.01 | D18: 0.066 | E18: 0.006
... B28: 0.46 | C28: 0.09 | D28: 0.136 | E28: 0.012

Sheet Sheet 9
A1: Comparison of predicted growth and acetate secretion rates of single-gene deletion E. coli mutants with experimentally determined values
A2: Experimental data was taken from specified sources
A4: Model: iML1515 including protein allocation and enzymatic constraints
A5: Upper bounds of substrate uptake rates were constrained to measured values
A6: Errors were computed by simulating the hightest and lowest expected glucose uptake rate according to the confidence intervals of experimentally determined uptake rates
A7: Excess enzyme sector was parametrized according to a methodically derived maximum glucose uptake rate of 9.82 mmol/gDW/h
B10: Deleted gene
C11: Experimental | E11: Predicted | G11: Experimental | I11: Predicted | K11: Source
C12: Growth rate | D12: Error | E12: Growth rate | F12: Error | G12: Acetate secretion rate | H12: Error | I12: Acetate secretion rate | J12: Error
C13: 1/h | E13: 1/h | G13: mmol/gDW/h | I13: mmol/gDW/h
B14: Wild type | C14: 0.63258 | D14: 0.0094 | E14: 0.58578 | F14: 0.01313 | G14: 6.05062 | H14: 0.15283 | I14: 5.5232 | J14: 0.23482 | K14: Long et al. 2016 (doi: 10.1016/j.ymben.2016.05.006)
B15: crr | C15: 0.43723 | D15: 0.00881 | E15: 0.38426 | F15: 0.0114 | G15: 3.11913 | H15: 0.11961 | I15: 1.92657 | J15: 0.20297
B16: glk | C16: 0.5643 | D16: 0.01507 | E16: 0.60173 | F16: 0.01601 | G16: 6.80538 | H16: 0.21002 | I16: 5.80856 | J16: 0.28639
B17: zwf | C17: 0.5736 | D17: 0.00978 | E17: 0.59792 | F17: 0.01217 | G17: 6.83698 | H17: 0.17449 | I17: 5.92394 | J17: 0.22659
B18: gnd | C18: 0.5284 | D18: 0.00954 | E18: 0.55387 | F18: 0.02248 | G18: 7.58186 | H18: 0.36096 | I18: 4.85617 | J18: 0.3708
B19: rpe | C19: 0.29967 | D19: 0.02098 | E19: 0.32351 | F19: 0.02256 | G19: 2.54496 | H19: 0.2183 | I19: 0.85428 | J19: 0.40238
B20: edd | C20: 0.5846 | D20: 0.01175 | E20: 0.53999 | F20: 0.01621 | G20: 5.84754 | H20: 0.20576 | I20: 4.70416 | J20: 0.28986
B21: eda | C21: 0.55123 | D21: 0.00585 | E21: 0.59855 | F21: 0.01433 | G21: 7.28199 | H21: 0.2055 | I21: 5.75164 | J21: 0.25635
B22: pgi | C22: 0.19093 | D22: 0.00299 | E22: 0.16012 | F22: 0.00448 | G22: 0.03524 | H22: 0.000893137 | I22: 0 | J22: 0
B23: tpiA | C23: 0.16647 | D23: 0.01063 | E23: 0.17127 | F23: 0.01288 | G23: 0.92228 | H23: 0.06311 | I23: 0 | J23: 0
B24: Wild type | C24: 0.63 | D24: 0.03 | E24: 0.60585 | F24: 0.0312 | G24: 4.5 | H24: 0.7 | I24: 5.88209 | J24: 0.55808 | K24: Fong et al. 2006 (doi: 10.1074/jbc.M510016200)
B25: pgi | C25: 0.17 | D25: 0 | E25: 0.17485 | F25: 0.00855 | G25: 0.1 | H25: 0.1 | I25: 0 | J25: 0
B26: ppc | C26: 0.22 | D26: 0.01 | E26: 0.23576 | F26: 0 | G26: 1.1 | H26: 0 | I26: 0 | J26: 0
B27: tpi | C27: 0.18 | D27: 0.02 | E27: 0.20169 | F27: 0 | G27: 0.2 | H27: 0.1 | I27: 0 | J27: 0

Sheet Sheet 10
A1: Comparison of predicted relative growth, glucose uptake and acetate secretion rates of single-gene deletion E. coli mutants with experimentally determined values
A3: Model: iML1515 including protein allocation and enzymatic constraints
A4: Gucose uptake rates were estimated according to a maximum overexpression capacity of single enzymes of 16 nmol/gDW/h
A5: All rates were normalized with the predicted and experimentally determined wild-type rates, respectively
B7: Deleted gene | C7: Relative growth rate | E7: Relative acetate production rate | G7: Relative substrate uptake rate | I7: Source
C8: 1/h | E8: mmol/gDW/h | G8: mmol/gDW/h
C9: Experimental | D9: Predicted | E9: Experimental | F9: Predicted | G9: Experimental | H9: Predicted
B10: pgi | C10: 0.26984 | D10: 0.38357 | E10: 0.02222 | F10: 0.01663 | G10: 0.26136 | H10: 0.33489 | I10: Fong et al. 2006 (doi: 10.1074/jbc.M510016200)
B11: ppc | C11: 0.34921 | D11: 0.37955 | E11: 0.24444 | F11: 0 | G11: 0.34091 | H11: 0.32737
B12: tpiA | C12: 0.28571 | D12: 0.30987 | E12: 0.04444 | F12: 0 | G12: 0.30682 | H12: 0.28226
B13: ptsG | C13: 0.39888 | D13: 0.45928 | E13: 0 | F13: 0.09382 | G13: 0.28861 | H13: 0.41758 | I13: Long et al. 2016 (doi: 10.1016/j.ymben.2016.05.006)
B14: zwf | C14: 0.90673 | D14: 0.98304 | E14: 1.12997 | F14: 1.00733 | G14: 1.03596 | H14: 0.99646
B15: gnd | C15: 0.83528 | D15: 1.01628 | E15: 1.25308 | F15: 1.25476 | G15: 0.94576 | H15: 1.07916
B16: rpe | C16: 0.47371 | D16: 1.02088 | E16: 0.42061 | F16: 1.25629 | G16: 0.50555 | H16: 1.07916
B17: pgi | C17: 0.30182 | D17: 0.38357 | E17: 0.00582 | F17: 0.01663 | G17: 0.25096 | H17: 0.33489
B18: tpiA | C18: 0.26315 | D18: 0.30987 | E18: 0.15243 | F18: 0 | G18: 0.27427 | H18: 0.28226
B19: zwf | C19: 0.90476 | D19: 0.98304 | E19: 0.97408 | F19: 1.00733 | G19: 0.9016 | H19: 0.99646 | I19: Long et al. 2019 (doi: 10.1016/j.ymben.2019.08.003)
B20: gnd | C20: 0.88889 | D20: 1.01628 | E20: 1.284 | F20: 1.25476 | G20: 1.01886 | H20: 1.07916
B21: rpe | C21: 0.46032 | D21: 1.02088 | E21: 0.28887 | F21: 1.25629 | G21: 0.41788 | H21: 1.07916
B22: pgi | C22: 0.30159 | D22: 0.38357 | E22: 0.00444 | F22: 0.01663 | G22: 0.24061 | H22: 0.33489
B23: tpiA | C23: 0.26984 | D23: 0.30987 | E23: 0.21774 | F23: 0 | G23: 0.37987 | H23: 0.28226

Sheet Sheet 11
A1: Comparison of predicted intracellular flux rates of single-gene deletion mutants with experimentally determined values
A2: Experimental flux data taken from Long et al. 2019 (doi: 10.1016/j.ymben.2019.08.003)
A4: Model: iML1515 including protein allocation and enzymatic constraints
A5: Gucose uptake rates were estimated according to a maximum overexpression capacity of single enzymes of 16 nmol/gDW/h
A6: All rates were normalized with the predicted and experimentally determined glucose uptake rates
C9: Wild-type | F9: Deleted gene: | G9: gnd | K9: pgi | O9: rpe | S9: tpiA | W9: zwf
B10: Reaction ID (iML1515) | C10: Flux rate | F10: Reaction ID (iML1515) | G10: Flux rate | J10: Reaction ID (iML1515) | K10: Flux rate | N10: Reaction ID (iML1515) | O10: Flux rate | R10: Reaction ID (iML1515) | S10: Flux rate | V10: Reaction ID (iML1515) | W10: Flux rate
C11: mmol/gDW/h | G11: mmol/gDW/h | K11: mmol/gDW/h | O11: mmol/gDW/h | S11: mmol/gDW/h | W11: mmol/gDW/h
C12: Experimental | D12: Predicted | G12: Experimental | H12: Predicted | K12: Experimental | L12: Predicted | O12: Experimental | P12: Predicted | S12: Experimental | T12: Predicted | W12: Experimental | X12: Predicted
B13: GLCptspp | C13: 1 | D13: 1 | F13: GLCptspp | G13: 1 | H13: 1 | J13: GLCptspp | K13: 1 | L13: 1 | N13: GLCptspp | O13: 1 | P13: 1 | R13: GLCptspp | S13: 1 | T13: 1 | V13: GLCptspp | W13: 1 | X13: 1
B14: PGI_f | C14: 0.69156 | D14: 0.59861 | F14: PGI_f | G14: 0.67147 | H14: 0.52524 | J14: PGI_f | K14: -0.002 | L14: 0 | N14: PGI_f | O14: 0.87519 | P14: 0.53691 | R14: PGI_f | S14: 0.81327 | T14: 0 | V14: PGI_f | W14: 0.97584 | X14: 0.9864
B15: FBA_f | C15: 0.80878 | D15: 0.80029 | F15: FBA_f | G15: 0.62035 | H15: 0.4696 | J15: FBA_f | K15: 0.50384 | L15: 0.58879 | N15: FBA_f | O15: 0.86881 | P15: 0.5302 | R15: FBA_f | S15: 0.87262 | T15: 0.0138 | V15: FBA_f | W15: 0.91103 | X15: 0.9509
B16: TPI_f | C16: 0.80878 | D16: 0.78956 | F16: TPI_f | G16: 0.62035 | H16: 0.45918 | J16: TPI_f | K16: 0.50384 | L16: 0.5761 | N16: TPI_f | O16: 0.86881 | P16: 0.51973 | R16: TPI_f | S16: 0.01645 | T16: 0 | V16: TPI_f | W16: 0.91103 | X16: 0.93956
B17: GAPD_f | C17: 1.67463 | D17: 1.68611 | F17: GAPD_f | G17: 1.50172 | H17: 1.35876 | J17: GAPD_f | K17: 1.31878 | L17: 1.45385 | N17: GAPD_f | O17: 1.72801 | P17: 1.41879 | R17: GAPD_f | S17: 0.92308 | T17: 1.20738 | V17: GAPD_f | W17: 1.77789 | X17: 1.86786
B18: ENO_f | C18: 1.54069 | D18: 1.68611 | F18: ENO_f | G18: 1.39379 | H18: 1.35876 | J18: ENO_f | K18: 1.16648 | L18: 1.45385 | N18: ENO_f | O18: 1.58962 | P18: 1.41879 | R18: ENO_f | S18: 0.8351 | T18: 1.06754 | V18: ENO_f | W18: 1.64455 | X18: 1.86786
B19: PYK | C19: 0.24065 | D19: 0 | F19: PYK | G19: 0.13024 | H19: 0 | J19: PYK | K19: 0.03394 | L19: 0 | N19: PYK | O19: 0.27903 | P19: 0 | R19: PYK | S19: -0.08384 | T19: 0 | V19: PYK | W19: 0.30101 | X19: 0
B20: G6PDH2r_f | C20: 0.28758 | D20: 0.38852 | F20: G6PDH2r_f | G20: 0.29897 | H20: 0.46227 | J20: G6PDH2r_f | K20: 0.94301 | L20: 0.98479 | N20: G6PDH2r_f | O20: 0.10075 | P20: 0.45054 | R20: G6PDH2r_f | S20: 0.16529 | T20: 3.09687 | V20: G6PDH2r_f | W20: 0.00246 | X20: 0
B21: GND | C21: 0.27549 | D21: 0.38852 | F21: GND | G21: 1e-12 | H21: 0 | J21: GND | K21: 0.86903 | L21: 0.98479 | N21: GND | O21: 0.0912 | P21: 0.07385 | R21: GND | S21: 0.15049 | T21: 2.79085 | V21: GND | W21: 9.99954e-13 | X21: 0.03763
B22: RPE_f | C22: 0.12315 | D22: 0.20856 | F22: RPE_f | G22: 0 | H22: 0 | J22: RPE_f | K22: 0.51431 | L22: 0.5969 | N22: RPE_f | O22: 0 | P22: 0 | R22: RPE_f | S22: 0.06364 | T22: 1.79576 | V22: RPE_f | W22: 0 | X22: 0
B23: RPE_b | C23: 0 | D23: 0 | F23: RPE_b | G23: 0.04632 | H23: 0.04898 | J23: RPE_b | K23: 0 | L23: 0 | N23: RPE_b | O23: 0.000276823 | P23: 0 | R23: RPE_b | S23: 0 | T23: 0 | V23: RPE_b | W23: 0.05875 | X23: 0.02824
B24: RPI_f | C24: 0.15234 | D24: 0 | F24: RPI_f | G24: 0.04632 | H24: 0 | J24: RPI_f | K24: 0.35473 | L24: 0 | N24: RPI_f | O24: 0.09147 | P24: 0 | R24: RPI_f | S24: 0.08686 | T24: 0 | V24: RPI_f | W24: 0.05875 | X24: 0
... B47: MGSA | C47: 0 | D47: 0 | F47: MGSA | G47: 0 | H47: 0 | J47: MGSA | K47: 0 | L47: 0 | N47: MGSA | O47: 0 | P47: 0 | R47: MGSA | S47: 0.85617 | T47: 0 | V47: MGSA | W47: 0 | X47: 0

Sheet Sheet 12
A1: Comparison between experimentally determined and predicted growth and acetate secretion rates using several substrates as sole carbon sources.
A2: Experimental data taken from Gerosa et al. (2015) (doi: 10.1016/j.cels.2015.09.008)
A4: Model: iML1515 including protein allocation and enzymatic constraints
A5: Upper bound of substrate uptake rates were constrained to methodically determined maximum substrate uptake rates according to a maximum total protein synthesis rate of 2.04 mumol/gDW/h
B8: Substrate | C8: Growth rate | E8: Acetate production rate | G8: Substrate uptake rate
C9: 1/h | E9: mmol/gDW/h | G9: mmol/gDW/h
C10: Experimental | D10: Predicted | E10: Experimental | F10: Predicted | G10: Experimental | H10: Predicted
B11: Glucose | C11: 0.65 | D11: 0.6695 | E11: 6.83 | F11: 7.02056 | G11: 9.65 | H11: 9.82
B12: Fructose | C12: 0.49 | D12: 0.66822 | E12: 3.33 | F12: 6.01333 | G12: 8.33 | H12: 9.61
B13: Galactose | C13: 0.18 | D13: 0.63515 | E13: 0 | F13: 6.45692 | G13: 1.969 | H13: 9.39
B14: Acetate | C14: 0.29 | D14: 0.36762 | E14: - | F14: 0 | G14: 13.58 | H14: 18.44
B15: Glycerol | C15: 0.49 | D15: 0.67794 | E15: 0.6 | F15: 2.34803 | G15: 4.94 | H15: 14.89
B16: Gluconate | C16: 0.59 | D16: 0.60392 | E16: 5 | F16: 5.87586 | G16: 7.28 | H16: 9.52
B17: Pyruvate | C17: 0.39 | D17: 0.61427 | E17: 11.91 | F17: 39.83266 | G17: 26.71 | H17: 53
B18: Succinate | C18: 0.51 | D18: 0.6954 | E18: 3.32 | F18: 14.74866 | G18: 15.9 | H18: 24.02
B19: Xylose | C19: 0.55 | D19: 0.5825 | E19: - | F19: 15.88378 | G19: -- | H19: 14.19
B20: Mannose | C20: 0.47 | D20: 0.47207 | E20: - | F20: 2.59851 | G20: -- | H20: 6.44
B21: Glucosamine | C21: 0.46 | D21: 0.66074 | E21: - | F21: 5.78166 | G21: -- | H21: 9.46
B22: Fumarate | C22: 0.42 | D22: 0.69419 | E22: - | F22: 17.25486 | G22: -- | H22: 26.51
B23: Glucose (anaerobic) | C23: 0.33 | D23: 0.46143 | E23: 7.3 | F23: 7.1961 | G23: 13.1 | H23: 20.29
B24: Xylose (Anaerobic) | C24: 0.13 | D24: 0.33645 | E24: 5.5 | F24: 4.67934 | G24: 10.8 | H24: 26.56

Sheet Sheet 13
A1: Comparison of predicted growth and acetate secretion rates of single-gene deletion E. coli mutants with experimentally determined values
A2: Experimental data was taken from specified sources
A4: Model: iML1515 including protein allocation and enzymatic constraints
A5: Upper bounds of substrate uptake rates were constrained to measured values
A6: Errors were computed by simulating the hightest and lowest expected glucose uptake rate according to the confidence intervals of experimentally determined uptake rates
A7: Excess enzyme sector was parametrized according to a methodically derived maximum glucose uptake rate of 9.82 mmol/gDW/h
B10: Deleted gene
C11: Experimental | E11: Predicted | G11: Experimental | I11: Predicted | K11: Source
C12: Growth rate | D12: Error | E12: Growth rate | F12: Error | G12: Acetate secretion rate | H12: Error | I12: Acetate secretion rate | J12: Error
C13: 1/h | E13: 1/h | G13: mmol/gDW/h | I13: mmol/gDW/h
B14: Wild type | C14: 0.63258 | D14: 0.0094 | E14: 0.6695 | F14: 0 | G14: 6.05062 | H14: 0.15283 | I14: 7.02056 | J14: 0 | K14: Long et al. 2016 (doi: 10.1016/j.ymben.2016.05.006)
B15: crr | C15: 0.43723 | D15: 0.00881 | E15: 0.6695 | F15: 0 | G15: 3.11913 | H15: 0.11961 | I15: 7.02063 | J15: 0
B16: glk | C16: 0.5643 | D16: 0.01507 | E16: 0.6695 | F16: 0 | G16: 6.80538 | H16: 0.21002 | I16: 7.02063 | J16: 0
B17: zwf | C17: 0.5736 | D17: 0.00978 | E17: 0.66068 | F17: 0 | G17: 6.83698 | H17: 0.17449 | I17: 7.09232 | J17: 0
B18: gnd | C18: 0.5284 | D18: 0.00954 | E18: 0.66515 | F18: 0 | G18: 7.58186 | H18: 0.36096 | I18: 6.69196 | J18: 0
B19: rpe | C19: 0.29967 | D19: 0.02098 | E19: 0.66801 | F19: 0 | G19: 2.54496 | H19: 0.2183 | I19: 6.70816 | J19: 0
B20: edd | C20: 0.5846 | D20: 0.01175 | E20: 0.6695 | F20: 0 | G20: 5.84754 | H20: 0.20576 | I20: 7.0206 | J20: 0
B21: eda | C21: 0.55123 | D21: 0.00585 | E21: 0.6695 | F21: 0 | G21: 7.28199 | H21: 0.2055 | I21: 7.02066 | J21: 0
B22: pgi | C22: 0.19093 | D22: 0.00299 | E22: 0.66101 | F22: 0 | G22: 0.03524 | H22: 0.000893137 | I22: 6.7906 | J22: 0
B23: tpiA | C23: 0.16647 | D23: 0.01063 | E23: 0.659 | F23: 0 | G23: 0.92228 | H23: 0.06311 | I23: 6.37796 | J23: 0
B24: Wild type | C24: 0.63 | D24: 0.03 | E24: 0.6695 | F24: 0 | G24: 4.5 | H24: 0.7 | I24: 7.02056 | J24: 0 | K24: Fong et al. 2006 (doi: 10.1074/jbc.M510016200)
B25: pgi | C25: 0.17 | D25: 0 | E25: 0.66101 | F25: 0 | G25: 0.1 | H25: 0.1 | I25: 6.7906 | J25: 0
B26: ppc | C26: 0.22 | D26: 0.01 | E26: 0.66338 | F26: 0 | G26: 1.1 | H26: 0 | I26: 6.84483 | J26: 0
B27: tpi | C27: 0.18 | D27: 0.02 | E27: 0.659 | F27: 0 | G27: 0.2 | H27: 0.1 | I27: 6.37796 | J27: 0

Sheet Sheet 14
A1: Comparison of phenotypic predictions between wild-type and gene-deletion mutant model
A4: Model: iML1515 including protein allocation and enzymatic constraints
A5: Upper bounds of substrate uptake rates were constrained to measured values (taken from specified sources)
A6: Errors were computed by simulating the hightest and lowest expected glucose uptake rate according to the confidence intervals of experimentally determined uptake rates
A7: Excess enzyme sector was parametrized according to a methodically derived maximum glucose uptake rate of 9.82 mmol/gDW/h
A8: In the wild-type model does the specified gene is not deleted
B10: Deleted gene
C11: Wild-type model | E11: Gene-deletion model | G11: Wild-type model | I11: Gene-deletion model | K11: Source
C12: Growth rate | D12: Error | E12: Growth rate | F12: Error | G12: Acetate secretion rate | H12: Error | I12: Acetate secretion rate | J12: Error
C13: 1/h | E13: 1/h | G13: mmol/gDW/h | I13: mmol/gDW/h
B14: Wild type | C14: 0.58578 | D14: 0.01313 | E14: 0.58578 | F14: 0.01313 | G14: 5.5232 | H14: 0.23482 | I14: 5.5232 | J14: 0.23482 | K14: Long et al. 2016 (doi: 10.1016/j.ymben.2016.05.006)
B15: crr | C15: 0.38426 | D15: 0.0114 | E15: 0.38426 | F15: 0.0114 | G15: 1.92653 | H15: 0.20296 | I15: 1.92657 | J15: 0.20297
B16: glk | C16: 0.60173 | D16: 0.01601 | E16: 0.60173 | F16: 0.01601 | G16: 5.80843 | H16: 0.28639 | I16: 5.80856 | J16: 0.28639
B17: zwf | C17: 0.6048 | D17: 0.01255 | E17: 0.59792 | F17: 0.01217 | G17: 5.86341 | H17: 0.2244 | I17: 5.92394 | J17: 0.22659
B18: gnd | C18: 0.55708 | D18: 0.02271 | E18: 0.55387 | F18: 0.02248 | G18: 5.00982 | H18: 0.40614 | I18: 4.85617 | J18: 0.3708
B19: rpe | C19: 0.32361 | D19: 0.02256 | E19: 0.32351 | F19: 0.02256 | G19: 0.84639 | H19: 0.40183 | I19: 0.85428 | J19: 0.40238
B20: edd | C20: 0.53999 | D20: 0.01621 | E20: 0.53999 | F20: 0.01621 | G20: 4.70405 | H20: 0.28986 | I20: 4.70416 | J20: 0.28986
B21: eda | C21: 0.59855 | D21: 0.01433 | E21: 0.59855 | F21: 0.01433 | G21: 5.75153 | H21: 0.25635 | I21: 5.75164 | J21: 0.25635
B22: pgi | C22: 0.16098 | D22: 0.0045 | E22: 0.16012 | F22: 0.00448 | G22: 0 | H22: 0 | I22: 0 | J22: 0
B23: tpiA | C23: 0.17795 | D23: 0.01357 | E23: 0.17127 | F23: 0.01288 | G23: 0 | H23: 0 | I23: 0 | J23: 0
B24: Wild type | C24: 0.60585 | D24: 0.0312 | E24: 0.60585 | F24: 0.0312 | G24: 5.88209 | H24: 0.55808 | I24: 5.88209 | J24: 0.55808 | K24: Fong et al. 2006 (doi: 10.1074/jbc.M510016200)
B25: pgi | C25: 0.17576 | D25: 0.00859 | E25: 0.17485 | F25: 0.00855 | G25: 0 | H25: 0 | I25: 0 | J25: 0
B26: ppc | C26: 0.23576 | D26: 0 | E26: 0.23576 | F26: 0 | G26: 0 | H26: 0 | I26: 0 | J26: 0
B27: tpi | C27: 0.21008 | D27: 0 | E27: 0.20169 | F27: 0 | G27: 0 | H27: 0 | I27: 0 | J27: 0

Sheet Sheet 15
A1: Comparison of predicted relative growth, glucose uptake and acetate secretion rates of single-gene deletion E. coli mutants with experimentally determined values
A3: Model: iML1515 including protein allocation and enzymatic constraints
A4: Here, the kcat values of both Entner-Doudoroff pathway steps were decreased to 2.5% of the the original values
A5: Gucose uptake rates were estimated according to a maximum overexpression capacity of single enzymes of 14.3 nmol/gDW/h
A6: All rates were normalized with the predicted and experimentally determined wild-type rates, respectively
B8: Deleted gene | C8: Relative growth rate | E8: Relative acetate production rate | G8: Relative substrate uptake rate | I8: Source
C9: 1/h | E9: mmol/gDW/h | G9: mmol/gDW/h
C10: Experimental | D10: Predicted | E10: Experimental | F10: Predicted | G10: Experimental | H10: Predicted
B11: pgi | C11: 0.26984 | D11: 0.35992 | E11: 0.02222 | F11: 0 | G11: 0.26136 | H11: 0.31272 | I11: Fong et al. 2006 (doi: 10.1074/jbc.M510016200)
B12: ppc | C12: 0.34921 | D12: 0.36176 | E12: 0.24444 | F12: 0 | G12: 0.34091 | H12: 0.31272
B13: tpiA | C13: 0.28571 | D13: 0.36303 | E13: 0.04444 | F13: 0.04475 | G13: 0.30682 | H13: 0.35037
B14: ptsG | C14: 0.39888 | D14: 0.43304 | E14: 0 | F14: 0.04841 | G14: 0.28861 | H14: 0.38803 | I14: Long et al. 2016 (doi: 10.1016/j.ymben.2016.05.006)
B15: zwf | C15: 0.90673 | D15: 0.95271 | E15: 1.12997 | F15: 0.9432 | G15: 1.03596 | H15: 0.96043
B16: gnd | C16: 0.83528 | D16: 0.93764 | E16: 1.25308 | F16: 0.9316 | G16: 0.94576 | H16: 0.94537
B17: rpe | C17: 0.47371 | D17: 0.99384 | E17: 0.42061 | F17: 1.02553 | G17: 0.50555 | H17: 1.00562
B18: pgi | C18: 0.30182 | D18: 0.35992 | E18: 0.00582 | F18: 0 | G18: 0.25096 | H18: 0.31272
B19: tpiA | C19: 0.26315 | D19: 0.36303 | E19: 0.15243 | F19: 0.04475 | G19: 0.27427 | H19: 0.35037
B20: zwf | C20: 0.90476 | D20: 0.95271 | E20: 0.97408 | F20: 0.9432 | G20: 0.9016 | H20: 0.96043 | I20: Long et al. 2019 (doi: 10.1016/j.ymben.2019.08.003)
B21: gnd | C21: 0.88889 | D21: 0.93764 | E21: 1.284 | F21: 0.9316 | G21: 1.01886 | H21: 0.94537
B22: rpe | C22: 0.46032 | D22: 0.99384 | E22: 0.28887 | F22: 1.02553 | G22: 0.41788 | H22: 1.00562
B23: pgi | C23: 0.30159 | D23: 0.35992 | E23: 0.00444 | F23: 0 | G23: 0.24061 | H23: 0.31272
B24: tpiA | C24: 0.26984 | D24: 0.36303 | E24: 0.21774 | F24: 0.04475 | G24: 0.37987 | H24: 0.35037

Sheet Sheet 16
A1: Comparison of predicted intracellular flux rates of single-gene deletion mutants with experimentally determined values
A2: Experimental flux data taken from Long et al. 2019 (doi: 10.1016/j.ymben.2019.08.003)
A4: Model: iML1515 including protein allocation and enzymatic constraints
A5: Here, the kcat values of both Entner-Doudoroff pathway steps were decreased to 2.5% of the the original values
A6: Gucose uptake rates were estimated according to a maximum overexpression capacity of single enzymes of 16 nmol/gDW/h
A7: All rates were normalized with the predicted and experimentally determined glucose uptake rates
C10: Wild-type | F10: Deleted gene: | G10: gnd | K10: pgi | O10: rpe | S10: tpiA | W10: zwf
B11: Reaction ID (iML1515) | C11: Flux rate | F11: Reaction ID (iML1515) | G11: Flux rate | J11: Reaction ID (iML1515) | K11: Flux rate | N11: Reaction ID (iML1515) | O11: Flux rate | R11: Reaction ID (iML1515) | S11: Flux rate | V11: Reaction ID (iML1515) | W11: Flux rate
C12: mmol/gDW/h | G12: mmol/gDW/h | K12: mmol/gDW/h | O12: mmol/gDW/h | S12: mmol/gDW/h | W12: mmol/gDW/h
C13: Experimental | D13: Predicted | G13: Experimental | H13: Predicted | K13: Experimental | L13: Predicted | O13: Experimental | P13: Predicted | S13: Experimental | T13: Predicted | W13: Experimental | X13: Predicted
B14: GLCptspp | C14: 1 | D14: 1 | F14: GLCptspp | G14: 1 | H14: 1 | J14: GLCptspp | K14: 1 | L14: 1 | N14: GLCptspp | O14: 1 | P14: 1 | R14: GLCptspp | S14: 1 | T14: 1 | V14: GLCptspp | W14: 1 | X14: 1
B15: PGI_f | C15: 0.69156 | D15: 0.6846 | F15: PGI_f | G15: 0.67147 | H15: 0.98684 | J15: PGI_f | K15: -0.002 | L15: 0 | N15: PGI_f | O15: 0.87519 | P15: 0.91007 | R15: PGI_f | S15: 0.81327 | T15: 0 | V15: PGI_f | W15: 0.97584 | X15: 0.98635
B16: FBA_f | C16: 0.80878 | D16: 0.82691 | F16: FBA_f | G16: 0.62035 | H16: 0.92822 | J16: FBA_f | K16: 0.50384 | L16: 0.58839 | N16: FBA_f | O16: 0.86881 | P16: 0.90309 | R16: FBA_f | S16: 0.87262 | T16: 0.71544 | V16: FBA_f | W16: 0.91103 | X16: 0.95072
B17: TPI_f | C17: 0.80878 | D17: 0.81585 | F17: TPI_f | G17: 0.62035 | H17: 0.91725 | J17: TPI_f | K17: 0.50384 | L17: 0.57564 | N17: TPI_f | O17: 0.86881 | P17: 0.89219 | R17: TPI_f | S17: 0.01645 | T17: 0 | V17: TPI_f | W17: 0.91103 | X17: 0.93933
B18: GAPD_f | C18: 1.67463 | D18: 1.70918 | F18: GAPD_f | G18: 1.50172 | H18: 1.81146 | J18: GAPD_f | K18: 1.31878 | L18: 1.45277 | N18: GAPD_f | O18: 1.72801 | P18: 1.78713 | R18: GAPD_f | S18: 0.92308 | T18: 1.06727 | V18: GAPD_f | W18: 1.77789 | X18: 1.86736
B19: ENO_f | C19: 1.54069 | D19: 1.70918 | F19: ENO_f | G19: 1.39379 | H19: 1.81146 | J19: ENO_f | K19: 1.16648 | L19: 1.45277 | N19: ENO_f | O19: 1.58962 | P19: 1.78713 | R19: ENO_f | S19: 0.8351 | T19: 1.06727 | V19: ENO_f | W19: 1.64455 | X19: 1.86736
B20: PYK | C20: 0.24065 | D20: 0 | F20: PYK | G20: 0.13024 | H20: 0 | J20: PYK | K20: 0.03394 | L20: 0 | N20: PYK | O20: 0.27903 | P20: 0 | R20: PYK | S20: -0.08384 | T20: 0 | V20: PYK | W20: 0.30101 | X20: 0
B21: G6PDH2r_f | C21: 0.28758 | D21: 0.30213 | F21: G6PDH2r_f | G21: 0.29897 | H21: 0 | J21: G6PDH2r_f | K21: 0.94301 | L21: 0.98472 | N21: G6PDH2r_f | O21: 0.10075 | P21: 0.07686 | R21: G6PDH2r_f | S21: 0.16529 | T21: 1.18326 | V21: G6PDH2r_f | W21: 0.00246 | X21: 0
B22: GND | C22: 0.27549 | D22: 0.30213 | F22: GND | G22: 1e-12 | H22: 0 | J22: GND | K22: 0.86903 | L22: 0.98472 | N22: GND | O22: 0.0912 | P22: 0.07686 | R22: GND | S22: 0.15049 | T22: 1.18326 | V22: GND | W22: 9.99954e-13 | X22: 0.03777
B23: RPE_f | C23: 0.12315 | D23: 0.1494 | F23: RPE_f | G23: 0 | H23: 0 | J23: RPE_f | K23: 0.51431 | L23: 0.59655 | N23: RPE_f | O23: 0 | P23: 0 | R23: RPE_f | S23: 0.06364 | T23: 0.72423 | V23: RPE_f | W23: 0 | X23: 0
B24: RPE_b | C24: 0 | D24: 0 | F24: RPE_b | G24: 0.04632 | H24: 0.05159 | J24: RPE_b | K24: 0 | L24: 0 | N24: RPE_b | O24: 0.000276823 | P24: 0 | R24: RPE_b | S24: 0 | T24: 0 | V24: RPE_b | W24: 0.05875 | X24: 0.02834
B25: RPI_f | C25: 0.15234 | D25: 0 | F25: RPI_f | G25: 0.04632 | H25: 0 | J25: RPI_f | K25: 0.35473 | L25: 0 | N25: RPI_f | O25: 0.09147 | P25: 0 | R25: RPI_f | S25: 0.08686 | T25: 0 | V25: RPI_f | W25: 0.05875 | X25: 0
... B48: MGSA | C48: 0 | D48: 0 | F48: MGSA | G48: 0 | H48: 0 | J48: MGSA | K48: 0 | L48: 0 | N48: MGSA | O48: 0 | P48: 0 | R48: MGSA | S48: 0.85617 | T48: 0.70169 | V48: MGSA | W48: 0 | X48: 0

Sheet Sheet 17
A1: Curated enzymatic data used to build the protein allocation model
A2: kapp,max values were taken from Heckmann et al. 2018 (doi: 10.1038/s41467-018-07652-6) and base on a machine learning ensemble model
A3: Reaction IDs were taken from the BIGG database (http://bigg.ucsd.edu/)
B6: in vitro curated | C6: Machine learning ensemble model (Heckmann et al. 2018)
A7: Reaction ID | B7: Turnover number (kcat) [1/s] | C7: Turnover number (kapp,max) [1/s]
A8: ALATA_D2 | B8: 6.8625 | C8: 2.58347
A9: SHCHD2 | B9: 0.45 | C9: 0.34
A10: CPPPGO | B10: 0.003 | C10: 0.25
A11: GTHOr_f | B11: 733.3 | C11: 7.19489
A12: DHORD5 | B12: 82 | C12: 10.7381
A13: GLYCTO2 | B13: 15.7 | C13: 14.02374
A14: GLYCTO3 | B14: 15.7 | C14: 15.85726
A15: GLYCTO4 | B15: 15.7 | C15: 32.52162
A16: PFK_3 | B16: 31.0185 | C16: 58
A17: TRPS2 | B17: 3.695 | C17: 2.58589
A18: G3PD5 | B18: 33.3 | C18: 16.75727
A19: LEUTAi | B19: 15.655 | C19: 15.0274
... A1777: RHMND_b | B1777: 0.02 | C1777: 4.59069
